Workbook

Sheet ArticleDetails
A1: SERIAL NUMBER | B1: ARTICLE NUMBER | C1: DESTINATION COUNTRY NAME | D1: DESTINATION COUNTRY CODE | E1: MAIL NATURE TYPE | F1: MAIL TRANSPORT TYPE | G1: PHYSICAL WEIGHT | H1: DECLARED VALUE | I1: NON DELIVERY INSTRUCTIONS | J1: SENDER NAME | K1: SENDER COMPANY | L1: SENDER ADD LINE 1 | M1: SENDER ADD LINE 2 | N1: SENDER ADD LINE 3 | O1: SENDER CITY | P1: SENDER STATE | Q1: SENDER COUNTRY NAME | R1: SENDER COUNTRY CODE | S1: SENDER PINCODE | T1: SENDER EMAILID | U1: SENDER MOBILE | V1: SENDER ALT CONTACT | W1: SENDER KYC | X1: SENDER IOSS | Y1: RECEIVER NAME | Z1: RECEIVER COMPANY | AA1: RECEIVER ADD LINE 1 | AB1: RECEIVER ADD LINE 2 | AC1: RECEIVER ADD LINE 3 | AD1: RECEIVER CITY | AE1: RECEIVER STATE | AF1: RECEIVER ZIPCODE | AG1: RECEIVER EMAILID | AH1: RECEIVER MOBILE NO | AI1: RECEIVER ALT CONTACT | AJ1: RECEIVER KYC | AK1: RECEIVER TAX | AL1: INSURANCE TYPE | AM1: INSURED VALUE | AN1: POD FLAG | AO1: BULK REF | AP1: PICKUP ADDRESS FLAG | AQ1: DROP OFF PINCODE | AR1: PBE TYPE | AS1: PBE FILING | AT1: INCOTERMS
A2: 1 | D2: =_xlfn.LET(_xlpm.result,_xlfn.XLOOKUP(C2,Information!K:K,Information!L:L,""),IF(_xlpm.result="","",_xlpm.result)) | H2: 1000 | J2: sendername | K2: sendercompany | L2: senderadd1 | M2: senderadd2 | N2: senderadd3 | O2: sendercity | S2: 560001 | T2: sender@email.com | U2: 9876543210 | W2: YES | Y2: receivername | Z2: receivercompany | AA2: receiveradd1 | AB2: receiveradd2 | AC2: receiveradd3 | AD2: receivercity | AE2: receiverstate | AF2: 0 | AG2: receiver@email.com | AH2: 9876543210 | AM2: 0 | AO2: 12345 | AQ2: 560001 | AT2: DDP
A3: 2 | D3: =_xlfn.LET(_xlpm.result,_xlfn.XLOOKUP(C3,Information!K:K,Information!L:L,""),IF(_xlpm.result="","",_xlpm.result)) | H3: 1000 | J3: sendername | K3: sendercompany | L3: senderadd1 | M3: senderadd2 | N3: senderadd3 | O3: sendercity | S3: 560001 | T3: sender@email.com | U3: 9876543210 | W3: YES | Y3: receivername | Z3: receivercompany | AA3: receiveradd2 | AB3: receiveradd3 | AC3: receiveradd4 | AD3: receivercity | AE3: receiverstate | AF3: 0 | AG3: receiver@email.com | AH3: 9876543210 | AM3: 0 | AO3: 12345 | AQ3: 560001 | AT3: DDP
A4: 3 | D4: =_xlfn.LET(_xlpm.result,_xlfn.XLOOKUP(C4,Information!K:K,Information!L:L,""),IF(_xlpm.result="","",_xlpm.result))
D5: =_xlfn.LET(_xlpm.result,_xlfn.XLOOKUP(C5,Information!K:K,Information!L:L,""),IF(_xlpm.result="","",_xlpm.result))
D6: =_xlfn.LET(_xlpm.result,_xlfn.XLOOKUP(C6,Information!K:K,Information!L:L,""),IF(_xlpm.result="","",_xlpm.result))
D7: =_xlfn.LET(_xlpm.result,_xlfn.XLOOKUP(C7,Information!K:K,Information!L:L,""),IF(_xlpm.result="","",_xlpm.result))
D8: =_xlfn.LET(_xlpm.result,_xlfn.XLOOKUP(C8,Information!K:K,Information!L:L,""),IF(_xlpm.result="","",_xlpm.result))
D9: =_xlfn.LET(_xlpm.result,_xlfn.XLOOKUP(C9,Information!K:K,Information!L:L,""),IF(_xlpm.result="","",_xlpm.result))
D10: =_xlfn.LET(_xlpm.result,_xlfn.XLOOKUP(C10,Information!K:K,Information!L:L,""),IF(_xlpm.result="","",_xlpm.result))
D11: =_xlfn.LET(_xlpm.result,_xlfn.XLOOKUP(C11,Information!K:K,Information!L:L,""),IF(_xlpm.result="","",_xlpm.result))
D12: =_xlfn.LET(_xlpm.result,_xlfn.XLOOKUP(C12,Information!K:K,Information!L:L,""),IF(_xlpm.result="","",_xlpm.result))
D13: =_xlfn.LET(_xlpm.result,_xlfn.XLOOKUP(C13,Information!K:K,Information!L:L,""),IF(_xlpm.result="","",_xlpm.result))
D14: =_xlfn.LET(_xlpm.result,_xlfn.XLOOKUP(C14,Information!K:K,Information!L:L,""),IF(_xlpm.result="","",_xlpm.result))
D15: =_xlfn.LET(_xlpm.result,_xlfn.XLOOKUP(C15,Information!K:K,Information!L:L,""),IF(_xlpm.result="","",_xlpm.result))
D16: =_xlfn.LET(_xlpm.result,_xlfn.XLOOKUP(C16,Information!K:K,Information!L:L,""),IF(_xlpm.result="","",_xlpm.result))
... D500: =_xlfn.LET(_xlpm.result,_xlfn.XLOOKUP(C500,Information!K:K,Information!L:L,""),IF(_xlpm.result="","",_xlpm.result))

Sheet SubPieces
A1: SERIAL NUMBER REF | B1: HS CODE | C1: CTH CODE | D1: HS DESCRIPTION | E1: SP UNIT CD | F1: SP COUNT | G1: SP WEIGHT TOTAL | H1: SP NET WEIGHT | I1: SP ORIGIN COUNTRY CODE | J1: SP ORIGIN CURRENCY CODE | K1: SP COMM INVOICE NO | L1: SP COM INVOICE DATE(DD-MM-YYYY) | M1: SP INVOICE LSN | N1: SP INV CURRENCY CODE | O1: SP INV EXCHANGE RATE | P1: SP ASBL FOB VALUE | Q1: SP ASBL INR VAL | R1: SP TAX INVOICE NO | S1: SP TAX INVOICE DATE | T1: SP INV VALUE PU | U1: SP INV VALUE TOTAL | V1: ecommerce_url | W1: ecommerce_paytranid | X1: ecommerce_sku | Y1: igst_rate | Z1: igst_amount | AA1: export_duty_rate | AB1: export_duty_amount | AC1: cess_rate | AD1: cess_amount | AE1: compensation_cess_rate | AF1: compensation_cess_amount | AG1: tax_payment_mode_cd | AH1: tax_payment_channel_ref_no | AI1: tax_payment_channel_date | AJ1: tax_payment_channel_source | AK1: HTSUS CODE | AL1: DETAILED DESCRIPTION OF GOODS | AM1: PRIOR NOTICE PRODUCT CODE | AN1: SPECIAL PROGRAM INDICATOR | AO1: COUNTRY OF MELT AND POUR | AP1: PRIMARY COUNTRY OF SMELT | AQ1: SECONDARY COUNTRY OF SMELT | AR1: COUNTRY OF CAST | AS1: PARTNER GOVERNMENT AGENCY INFO | AT1: OTHER CBP INFORMATION | AU1: CUSTOMS ADDITIONAL DATA | AV1: PRODUCT ID | AW1: REGISTRATION CODE | AX1: BRAND NAME | AY1: COUNTRY HARVEST | AZ1: FACILITY REG NUMBER | BA1: IMPORT PERMIT NUMBER | BB1: INGREDIENTS | BC1: INTENDED USE | BD1: LOT BATCH NUMBER | BE1: MANUFACTURER REG NUMBER | BF1: OTHER INFORMATION | BG1: PACKAGE SIZE | BH1: PHYTOSANITARY CERT NUMBER | BI1: PLANT SPECIES | BJ1: PRIOR NOTICE NUMBER | BK1: PRODUCT CODE | BL1: REGISTRATION NUMBER | BM1: SCIENTIFIC NAME | BN1: SEED VARIETY | BO1: VETERINARY CERT | BP1: CERTIFIER ID | BQ1: VERSION ID | BR1: ACTIVE INGREDIENT | BS1: EPA REG NUMBER | BT1: FCC ID | BU1: FREQUENCY RANGE | BV1: MANUFACTURER | BW1: PESTICIDE CLASSIFICATION | BX1: PRODUCT TYPE | BY1: RADIO MODULE DETAILS | BZ1: AGE CATEGORY
A2: 1 | B2: 85287310 | D2: LED SCREEN DISPLAY (FOR PHONE) | E2: PC | F2: 1 | G2: 1600 | H2: 1600 | I2: IN | J2: INR | K2: SE-043 | L2: 46171 | M2: 1 | O2: 1 | P2: 1000 | Q2: 1000 | R2: SE-043 | S2: 46171 | U2: 1000 | V2: NO | W2: NO | X2: NO | Y2: 18 | Z2: 180
A3: 2 | B3: 85287310 | D3: LED SCREEN DISPLAY (FOR PHONE) | E3: PC | F3: 1 | G3: 1600 | H3: 1600 | I3: IN | J3: INR | K3: SE-044 | L3: 46171 | M3: 1 | O3: 1 | P3: 1000 | Q3: 1000 | R3: SE-044 | S3: 46171 | U3: 1000 | V3: NO | W3: NO | X3: NO | Y3: 18 | Z3: 180 | AK3: 8528730000

Sheet PickupAddress
A1: serial_no | B1: addressee_name | C1: company_name | D1: address_line1 | E1: address_line2 | F1: address_line3 | G1: city | H1: state | I1: pincode | J1: email_id | K1: alt_contact_no | L1: kyc_reference | M1: tax_reference | N1: mobile_no | O1: pickup_schedule_slot | P1: pickup_schedule_date

Sheet Information
A1: SHAPE OF ARTICLE | B1: BOOLEAN | C1: NON DELIVERY INSTRUCTIONS | D1: DESCRIPTION | E1: INSURANCE | F1: PICKUP SCHEDULE SLOT | G1: MAIL NATURE TYPE | H1: MAIL NATURE TYPE(Description) | I1: MAIL TRANSPORT TYPE | J1: DESCRIPTION | K1: Country Name | L1: Country Code | M1: SP UNIT CD | O1: S. No | P1: Code | Q1: Currency | R1: INCOTERMS | S1: SENDER COUNTRY NAME | T1: SENDER COUNTRY CODE | U1: STATE NAME | V1: AGE CATEGORY
A2: NROL | B2: TRUE | C2: A | D2: Abandoned | E2: DOP | F2: 10:00-13:00 | G2: 11 | H2: Sale of Goods | I2: AMS | J2: By Air | K2: Afganistan | L2: AF | M2: Code | N2: Description | O2: 1 | P2: Australian Dollar | Q2: AUD | R2: DDP | S2: India | T2: IN | U2: Andaman and Nicobar Islands | V2: UpTo12Years
A3: ROLL | B3: FALSE | C3: P | D3: RTS-Priority | F3: 13:00-16:00 | G3: 32 | H3: Commercial Sample | K3: Albania | L3: AL | M3: PC | N3: PIECES | O3: 2 | P3: Bahraini Dinar | Q3: BHD | R3: DAP | U3: Andhra Pradesh | V3: Above12Years
C4: N | D4: RTS-Non Priority | K4: Algeria | L4: DZ | M4: KG | N4: KILOGRAM | O4: 3 | P4: Canadian Dollar | Q4: CAD | U4: Arunachal Pradesh
K5: Andorra | L5: AD | M5: GM | N5: GRAMS | O5: 4 | P5: Chinese Yuan | Q5: CNY | U5: Assam
K6: Angola | L6: AO | M6: LT | N6: LITRE (FOR LIQUIDS) | O6: 5 | P6: Danish Kroner | Q6: DKK | U6: Bihar
K7: Anguilla | L7: AI | M7: CT | N7: CARAT (FOR JEWELLERY) | O7: 6 | P7: EURO | Q7: EUR | U7: Chandigarh
K8: Antigua/Barbuda | L8: AG | M8: MT | N8: METRES | O8: 7 | P8: Hong Kong Dollar | Q8: HKD | U8: Chhattisgarh
K9: Argentina | L9: AR | O9: 8 | P9: Kuwaiti Dinar | Q9: KWD | U9: Dadra & Nagar Haveli and Daman & Diu
K10: Armenia | L10: AM | O10: 9 | P10: New Zealand Dollar | Q10: NZD | U10: Delhi
K11: Aruba | L11: AW | M11: tax_payment_mode_cd | O11: 10 | P11: Norwegian Kroner | Q11: NOK | U11: Goa
K12: Ascension | L12: SH1 | M12: Code | N12: Description | O12: 11 | P12: Pound Sterling | Q12: GBP | U12: Gujarat
K13: Australia | L13: AU | M13: CLN | N13: Challan | O13: 12 | P13: Qatari Riyal | Q13: QAR | U13: Haryana
K14: Austria | L14: AT | O14: 13 | P14: Saudi Arabian Riyal | Q14: SAR | U14: Himachal Pradesh
K15: Azerbaijan | L15: AZ | O15: 14 | P15: Singapore Dollar | Q15: SGD | U15: Jammu and Kashmir
K16: Bahamas | L16: BS | O16: 15 | P16: South African Rand | Q16: ZAR | U16: Jharkhand
K17: Bahrain | L17: BH | O17: 16 | P17: Swedish Kroner | Q17: SEK | U17: Karnataka
K18: Bangladesh | L18: BD | M18: PBE TYPE | O18: 17 | P18: Swiss Franc | Q18: CHF | U18: Kerala
K19: Barbados | L19: BB | M19: Code | N19: Description | O19: 18 | P19: Turkish Lira | Q19: TRY | U19: Ladakh
K20: Belarus | L20: BY | M20: PBEIV | N20: Postal Bill of Export- IV(For Non eCommerce items) | O20: 19 | P20: UAE Dirham | Q20: AED | U20: Lakshadweep
A21: INSTRUCTIONS | K21: Belgium | L21: BE | M21: PBEIII | O21: 20 | P21: US Dollar | Q21: USD | U21: Madhya Pradesh
A22: 1 | B22: Please do not change the names of fields or the position in the first row | K22: Belize | L22: BZ | O22: 21 | P22: Japanese Yen | Q22: JPY | U22: Maharashtra
A23: 2 | B23: Please provide absolute values for Amount, Weight etc. Decimal values are not permitted | K23: Benin | L23: BJ | O23: 22 | P23: Korean Won | Q23: KRW | U23: Manipur
A24: 3 | B24: The Fields relating to Sum Totals viz., Total Value and Article Weight should correspond to the total value taken for all Sub-Pieces | K24: Bermuda | L24: BM | O24: 23 | P24: Indian Rupee | Q24: INR | U24: Meghalaya
A25: 4 | B25: Date format should be in DD-MM-YYYY and format in date ( Do not use text format) | K25: Bhutan | L25: BT | U25: Mizoram
A26: 5 | B26: Please use the specified codes as mentioned | K26: Bonaire, Sint Eustatius and Saba | L26: BQ | U26: Nagaland
A27: 6 | B27: If the customer is a registered eCommerce entity, then eCommerce details — i.e., eCommerce URL, eCommerce Transaction ID, and SKU (in SubPieces) — are mandatory | K27: Bosnia and Herzegovina | L27: BA | U27: Odisha
A28: 7 | B28: Keep the "PBE Filing" as SELF, it is considered as self-filing. | K28: Botswana | L28: BW | M28: PBE FILING | U28: Puducherry
A29: 8 | B29: In the Article tab, each article is assigned a serial number. In the Subpiece tab, each subpiece should reference the corresponding article's serial number. Suppose in the Article tab, serial number 1 corresponds to 5 books and 3 pens. Then, in the Subpiece tab, you should add 2 rows with serial number reference as 1 — one row for the "Book" subpiece and one row for the "Pen" subpiece | K29: Brazil | L29: BR | M29: Code | N29: Description | U29: Punjab
A30: 9 | B30: Please Keep the receiver/sender mobile no. with out using symbols like +, spaces etc | K30: British Virgin Islands | L30: VG | M30: SELF | N30: SELF | U30: Rajasthan
K31: Brunei Darussalam | L31: BN | U31: Sikkim
K32: Bulgaria | L32: BG | U32: Tamil Nadu
K33: Burkina Faso | L33: BF | U33: Telangana
K34: Burundi | L34: BI | U34: Tripura
K35: Cambodia | L35: KH | U35: Uttar Pradesh
K36: Cameroon | L36: CM | U36: Uttarakhand
K37: Canada | L37: CA | U37: West Bengal
K38: Cape Verde | L38: CV
K39: Cayman Islands | L39: KY
K40: Central African Republic | L40: CF
...
